Workbook

Sheet Summary
A1: Creator vendor fill — 2026-08
A2: Monthly run · freshness measured at 2026-08-31
A4: Creators requested | B4: =COUNTA(Creators!A5:A804) -> 800
A5: Channels requested | B5: =COUNTA(Channels!A5:A1893) -> 1889
A6: Creators complete (on leaderboard) | B6: =COUNTIF(Creators!H5:H804,"Yes") -> 355
A7: Share of creators complete | B7: =IFERROR(B6/B4,0) -> 0.44375
A8: Requested channels complete | B8: =COUNTIF(Channels!M5:M1893,"Yes") -> 1332
A9: Share of channels complete | B9: =IFERROR(B8/B5,0) -> 0.70513499
A10: Missing items (see Gaps) | B10: =COUNTA(Gaps!A5:A577) -> 573
A11: Tier order used | B11: T1 vendor_b → T2 vendor_a → T3 vendor_c
A14: Files this month (recognised automatically)
A15: File | B15: Recognised as | C15: Match | D15: Notes
A16: Aug request.xlsx | B16: request list | C16: 1
A17: Book1.xlsx | B17: vendor_c | C17: 0.875 | D17: new unused column(s): notes
A18: creator_data_0812.xlsx | B18: vendor_a | C18: 0.9
A19: social_export_aug.xlsx | B19: vendor_b | C19: 0.9
A21: Primary role of complete creators
A22: Pillar | B22: Creators | C22: Who it finds
A23: The Pulse | B23: =COUNTIF(Leaderboard!M5:M525,A23) -> 131 | C23: Attention: Creators who drive awareness and visibility
A24: The Lens | B24: =COUNTIF(Leaderboard!M5:M525,A24) -> 122 | C24: Affiliation: Creators who establish credibility and in-the-know appeal
A25: The Hub | B25: =COUNTIF(Leaderboard!M5:M525,A25) -> 102 | C25: Action: Creators who influence community participation and behavior
A27: Creators by number of channels requested
A28: Channels requested | B28: Creators | C28: Complete | D28: Share complete
A29: 3 of 3 | B29: =COUNTIF(Creators!$G$5:$G$804,"*/3") -> 465 | C29: =COUNTIFS(Creators!$G$5:$G$804,"*/3",Creators!$H$5:$H$804,"Yes") -> 171 | D29: =IFERROR(C29/B29,0) -> 0.36774194
A30: 2 of 3 | B30: =COUNTIF(Creators!$G$5:$G$804,"*/2") -> 159 | C30: =COUNTIFS(Creators!$G$5:$G$804,"*/2",Creators!$H$5:$H$804,"Yes") -> 71 | D30: =IFERROR(C30/B30,0) -> 0.44654088
A31: 1 of 3 | B31: =COUNTIF(Creators!$G$5:$G$804,"*/1") -> 176 | C31: =COUNTIFS(Creators!$G$5:$G$804,"*/1",Creators!$H$5:$H$804,"Yes") -> 113 | D31: =IFERROR(C31/B31,0) -> 0.64204545
A33: Requested channels
A34: Channel | B34: Requested | C34: Complete after last tier
A35: instagram | B35: 628 | C35: 0.6783
A36: tiktok | B36: 636 | C36: 0.6053
A37: youtube | B37: 625 | C37: 0.8336
A39: Colour key
A40: Tier 1 value
A41: Tier 2 value
A42: Tier 3 value
A43: Still missing

Sheet Leaderboard
A1: Creator Leaderboard — The Pulse · The Lens · The Hub
A2: Scores are 0–100 percentiles: each channel is compared with requested channels on the same platform (growth also within follower-size band), then averaged over the creator's requested channels. Blank Hub score = likes hidden on every channel.
A4: Creator | B4: Creator ID | C4: Country | D4: Category | E4: Channels | F4: Total followers | G4: The Pulse score | H4: The Pulse rank | I4: The Lens score | J4: The Lens rank | K4: The Hub score | L4: The Hub rank | M4: Primary role | N4: Confidence | O4: Sources
A5: Creator 1133 | B5: CR01133 | C5: CA | D5: education | E5: instagram | F5: 655880 | G5: 99.2 | H5: =IF(G5="","",RANK(G5,$G$5:$G$359)) -> 1 | I5: 5 | J5: =IF(I5="","",RANK(I5,$I$5:$I$359)) -> 350 | K5: 97.7 | L5: =IF(K5="","",RANK(K5,$K$5:$K$359)) -> 3 | M5: =IF(AND(N(G5)>=N(I5),N(G5)>=N(K5)),"The Pulse",IF(N(I5)>=N(K5),"The Lens","The Hub")) -> The Pulse | N5: High | O5: vendor_b
A6: Creator 85 | B6: CR00085 | C6: FR | D6: beauty | E6: youtube | F6: 6232 | G6: 98.6 | H6: =IF(G6="","",RANK(G6,$G$5:$G$359)) -> 2 | I6: 48.8 | J6: =IF(I6="","",RANK(I6,$I$5:$I$359)) -> 185 | K6: 50.4 | L6: =IF(K6="","",RANK(K6,$K$5:$K$359)) -> 165 | M6: =IF(AND(N(G6)>=N(I6),N(G6)>=N(K6)),"The Pulse",IF(N(I6)>=N(K6),"The Lens","The Hub")) -> The Pulse | N6: Medium | O6: vendor_a
A7: Creator 711 | B7: CR00711 | C7: BR | D7: fitness | E7: youtube | F7: 31387 | G7: 97.5 | H7: =IF(G7="","",RANK(G7,$G$5:$G$359)) -> 3 | I7: 78.2 | J7: =IF(I7="","",RANK(I7,$I$5:$I$359)) -> 44 | K7: 57 | L7: =IF(K7="","",RANK(K7,$K$5:$K$359)) -> 127 | M7: =IF(AND(N(G7)>=N(I7),N(G7)>=N(K7)),"The Pulse",IF(N(I7)>=N(K7),"The Lens","The Hub")) -> The Pulse | N7: Medium | O7: vendor_a
A8: Creator 1332 | B8: CR01332 | C8: JP | D8: food | E8: instagram | F8: 2350 | G8: 96.2 | H8: =IF(G8="","",RANK(G8,$G$5:$G$359)) -> 4 | I8: 26.8 | J8: =IF(I8="","",RANK(I8,$I$5:$I$359)) -> 301 | L8: =IF(K8="","",RANK(K8,$K$5:$K$359)) | M8: =IF(AND(N(G8)>=N(I8),N(G8)>=N(K8)),"The Pulse",IF(N(I8)>=N(K8),"The Lens","The Hub")) -> The Pulse | N8: Medium | O8: vendor_a, vendor_b
A9: Creator 41 | B9: CR00041 | C9: IN | D9: beauty | E9: instagram, youtube | F9: 195709 | G9: 95.4 | H9: =IF(G9="","",RANK(G9,$G$5:$G$359)) -> 5 | I9: 47.8 | J9: =IF(I9="","",RANK(I9,$I$5:$I$359)) -> 197 | K9: 69 | L9: =IF(K9="","",RANK(K9,$K$5:$K$359)) -> 59 | M9: =IF(AND(N(G9)>=N(I9),N(G9)>=N(K9)),"The Pulse",IF(N(I9)>=N(K9),"The Lens","The Hub")) -> The Pulse | N9: Medium | O9: vendor_a, vendor_b
A10: Creator 246 | B10: CR00246 | C10: US | E10: instagram | F10: 132660 | G10: 94.9 | H10: =IF(G10="","",RANK(G10,$G$5:$G$359)) -> 6 | I10: 34.3 | J10: =IF(I10="","",RANK(I10,$I$5:$I$359)) -> 268 | K10: 48.5 | L10: =IF(K10="","",RANK(K10,$K$5:$K$359)) -> 178 | M10: =IF(AND(N(G10)>=N(I10),N(G10)>=N(K10)),"The Pulse",IF(N(I10)>=N(K10),"The Lens","The Hub")) -> The Pulse | N10: High | O10: vendor_b
A11: Creator 357 | B11: CR00357 | C11: MX | D11: beauty | E11: instagram, tiktok, youtube | F11: 418556 | G11: 94.7 | H11: =IF(G11="","",RANK(G11,$G$5:$G$359)) -> 7 | I11: 73.8 | J11: =IF(I11="","",RANK(I11,$I$5:$I$359)) -> 60 | K11: 34.9 | L11: =IF(K11="","",RANK(K11,$K$5:$K$359)) -> 270 | M11: =IF(AND(N(G11)>=N(I11),N(G11)>=N(K11)),"The Pulse",IF(N(I11)>=N(K11),"The Lens","The Hub")) -> The Pulse | N11: Medium | O11: vendor_a, vendor_b
A12: Creator 1263 | B12: CR01263 | C12: CA | D12: finance | E12: tiktok | F12: 43020 | G12: 94.1 | H12: =IF(G12="","",RANK(G12,$G$5:$G$359)) -> 8 | I12: 43.6 | J12: =IF(I12="","",RANK(I12,$I$5:$I$359)) -> 222 | K12: 73.7 | L12: =IF(K12="","",RANK(K12,$K$5:$K$359)) -> 47 | M12: =IF(AND(N(G12)>=N(I12),N(G12)>=N(K12)),"The Pulse",IF(N(I12)>=N(K12),"The Lens","The Hub")) -> The Pulse | N12: High | O12: vendor_b
A13: Creator 182 | B13: CR00182 | C13: US | D13: gaming | E13: tiktok, youtube | F13: 173264 | G13: 93.8 | H13: =IF(G13="","",RANK(G13,$G$5:$G$359)) -> 9 | I13: 71.6 | J13: =IF(I13="","",RANK(I13,$I$5:$I$359)) -> 66 | K13: 68.5 | L13: =IF(K13="","",RANK(K13,$K$5:$K$359)) -> 61 | M13: =IF(AND(N(G13)>=N(I13),N(G13)>=N(K13)),"The Pulse",IF(N(I13)>=N(K13),"The Lens","The Hub")) -> The Pulse | N13: Medium | O13: vendor_a, vendor_b
A14: Creator 20 | B14: CR00020 | C14: FR | D14: beauty | E14: youtube | F14: 5060 | G14: 92.8 | H14: =IF(G14="","",RANK(G14,$G$5:$G$359)) -> 10 | I14: 25 | J14: =IF(I14="","",RANK(I14,$I$5:$I$359)) -> 303 | K14: 6.3 | L14: =IF(K14="","",RANK(K14,$K$5:$K$359)) -> 343 | M14: =IF(AND(N(G14)>=N(I14),N(G14)>=N(K14)),"The Pulse",IF(N(I14)>=N(K14),"The Lens","The Hub")) -> The Pulse | N14: Low | O14: vendor_a, vendor_c
A15: Creator 699 | B15: CR00699 | C15: CA | D15: beauty | E15: tiktok | F15: 30230 | G15: 92.5 | H15: =IF(G15="","",RANK(G15,$G$5:$G$359)) -> 11 | I15: 38.5 | J15: =IF(I15="","",RANK(I15,$I$5:$I$359)) -> 248 | K15: 94.7 | L15: =IF(K15="","",RANK(K15,$K$5:$K$359)) -> 7 | M15: =IF(AND(N(G15)>=N(I15),N(G15)>=N(K15)),"The Pulse",IF(N(I15)>=N(K15),"The Lens","The Hub")) -> The Hub | N15: High | O15: vendor_b
A16: Creator 361 | B16: CR00361 | C16: GB | D16: fitness | E16: tiktok, youtube | F16: 67965 | G16: 91.8 | H16: =IF(G16="","",RANK(G16,$G$5:$G$359)) -> 12 | I16: 36.4 | J16: =IF(I16="","",RANK(I16,$I$5:$I$359)) -> 258 | K16: 47.5 | L16: =IF(K16="","",RANK(K16,$K$5:$K$359)) -> 186 | M16: =IF(AND(N(G16)>=N(I16),N(G16)>=N(K16)),"The Pulse",IF(N(I16)>=N(K16),"The Lens","The Hub")) -> The Pulse | N16: Medium | O16: vendor_a, vendor_b
A17: Creator 497 | B17: CR00497 | C17: MX | E17: instagram | F17: 19100 | G17: 91.7 | H17: =IF(G17="","",RANK(G17,$G$5:$G$359)) -> 13 | I17: 52.6 | J17: =IF(I17="","",RANK(I17,$I$5:$I$359)) -> 164 | K17: 34 | L17: =IF(K17="","",RANK(K17,$K$5:$K$359)) -> 276 | M17: =IF(AND(N(G17)>=N(I17),N(G17)>=N(K17)),"The Pulse",IF(N(I17)>=N(K17),"The Lens","The Hub")) -> The Pulse | N17: High | O17: vendor_b
A18: Creator 423 | B18: CR00423 | C18: FR | D18: travel | E18: youtube | F18: 38310 | G18: 91.4 | H18: =IF(G18="","",RANK(G18,$G$5:$G$359)) -> 14 | I18: 80.5 | J18: =IF(I18="","",RANK(I18,$I$5:$I$359)) -> 35 | K18: 47.5 | L18: =IF(K18="","",RANK(K18,$K$5:$K$359)) -> 186 | M18: =IF(AND(N(G18)>=N(I18),N(G18)>=N(K18)),"The Pulse",IF(N(I18)>=N(K18),"The Lens","The Hub")) -> The Pulse | N18: High | O18: vendor_b
A19: Creator 1359 | B19: CR01359 | C19: DE | D19: tech | E19: instagram | F19: 33210 | G19: 89.8 | H19: =IF(G19="","",RANK(G19,$G$5:$G$359)) -> 15 | I19: 81.8 | J19: =IF(I19="","",RANK(I19,$I$5:$I$359)) -> 30 | K19: 59.4 | L19: =IF(K19="","",RANK(K19,$K$5:$K$359)) -> 110 | M19: =IF(AND(N(G19)>=N(I19),N(G19)>=N(K19)),"The Pulse",IF(N(I19)>=N(K19),"The Lens","The Hub")) -> The Pulse | N19: High | O19: vendor_b
A20: Creator 1118 | B20: CR01118 | C20: BR | D20: music | E20: instagram | F20: 14960 | G20: 87.9 | H20: =IF(G20="","",RANK(G20,$G$5:$G$359)) -> 16 | I20: 17.9 | J20: =IF(I20="","",RANK(I20,$I$5:$I$359)) -> 324 | L20: =IF(K20="","",RANK(K20,$K$5:$K$359)) | M20: =IF(AND(N(G20)>=N(I20),N(G20)>=N(K20)),"The Pulse",IF(N(I20)>=N(K20),"The Lens","The Hub")) -> The Pulse | N20: High | O20: vendor_b
A21: Creator 216 | B21: CR00216 | C21: BR | D21: music | E21: youtube | F21: 53974 | G21: 87.7 | H21: =IF(G21="","",RANK(G21,$G$5:$G$359)) -> 17 | I21: 44.5 | J21: =IF(I21="","",RANK(I21,$I$5:$I$359)) -> 215 | K21: 85.1 | L21: =IF(K21="","",RANK(K21,$K$5:$K$359)) -> 19 | M21: =IF(AND(N(G21)>=N(I21),N(G21)>=N(K21)),"The Pulse",IF(N(I21)>=N(K21),"The Lens","The Hub")) -> The Pulse | N21: Medium | O21: vendor_a
A22: Creator 481 | B22: CR00481 | C22: BR | D22: travel | E22: instagram | F22: 1207050 | G22: 86.8 | H22: =IF(G22="","",RANK(G22,$G$5:$G$359)) -> 18 | I22: 5.9 | J22: =IF(I22="","",RANK(I22,$I$5:$I$359)) -> 349 | K22: 6.5 | L22: =IF(K22="","",RANK(K22,$K$5:$K$359)) -> 342 | M22: =IF(AND(N(G22)>=N(I22),N(G22)>=N(K22)),"The Pulse",IF(N(I22)>=N(K22),"The Lens","The Hub")) -> The Pulse | N22: High | O22: vendor_b
A23: Creator 789 | B23: CR00789 | C23: GB | D23: gaming | E23: instagram, tiktok, youtube | F23: 117283 | G23: 86.7 | H23: =IF(G23="","",RANK(G23,$G$5:$G$359)) -> 19 | I23: 65.2 | J23: =IF(I23="","",RANK(I23,$I$5:$I$359)) -> 94 | K23: 61.8 | L23: =IF(K23="","",RANK(K23,$K$5:$K$359)) -> 96 | M23: =IF(AND(N(G23)>=N(I23),N(G23)>=N(K23)),"The Pulse",IF(N(I23)>=N(K23),"The Lens","The Hub")) -> The Pulse | N23: Low | O23: vendor_a, vendor_b, vendor_c
A24: Creator 238 | B24: CR00238 | C24: BR | D24: finance | E24: youtube | F24: 44236 | G24: 86.1 | H24: =IF(G24="","",RANK(G24,$G$5:$G$359)) -> 20 | I24: 74.7 | J24: =IF(I24="","",RANK(I24,$I$5:$I$359)) -> 52 | K24: 68.5 | L24: =IF(K24="","",RANK(K24,$K$5:$K$359)) -> 61 | M24: =IF(AND(N(G24)>=N(I24),N(G24)>=N(K24)),"The Pulse",IF(N(I24)>=N(K24),"The Lens","The Hub")) -> The Pulse | N24: Medium | O24: vendor_a
A25: Creator 305 | B25: CR00305 | C25: BR | D25: food | E25: tiktok, youtube | F25: 69424 | G25: 85.8 | H25: =IF(G25="","",RANK(G25,$G$5:$G$359)) -> 21 | I25: 12.7 | J25: =IF(I25="","",RANK(I25,$I$5:$I$359)) -> 338 | K25: 35.8 | L25: =IF(K25="","",RANK(K25,$K$5:$K$359)) -> 265 | M25: =IF(AND(N(G25)>=N(I25),N(G25)>=N(K25)),"The Pulse",IF(N(I25)>=N(K25),"The Lens","The Hub")) -> The Pulse | N25: Medium | O25: vendor_a, vendor_b
A26: Creator 1285 | B26: CR01285 | C26: FR | D26: travel | E26: youtube | F26: 54392 | G26: 84.5 | H26: =IF(G26="","",RANK(G26,$G$5:$G$359)) -> 22 | I26: 48.1 | J26: =IF(I26="","",RANK(I26,$I$5:$I$359)) -> 194 | K26: 62.7 | L26: =IF(K26="","",RANK(K26,$K$5:$K$359)) -> 90 | M26: =IF(AND(N(G26)>=N(I26),N(G26)>=N(K26)),"The Pulse",IF(N(I26)>=N(K26),"The Lens","The Hub")) -> The Pulse | N26: Medium | O26: vendor_a
A27: Creator 480 | B27: CR00480 | C27: CA | D27: gaming | E27: youtube | F27: 695720 | G27: 84.1 | H27: =IF(G27="","",RANK(G27,$G$5:$G$359)) -> 23 | I27: 78.3 | J27: =IF(I27="","",RANK(I27,$I$5:$I$359)) -> 43 | K27: 30.1 | L27: =IF(K27="","",RANK(K27,$K$5:$K$359)) -> 295 | M27: =IF(AND(N(G27)>=N(I27),N(G27)>=N(K27)),"The Pulse",IF(N(I27)>=N(K27),"The Lens","The Hub")) -> The Pulse | N27: Medium | O27: vendor_a
A28: Creator 1314 | B28: CR01314 | C28: MX | D28: travel | E28: instagram, tiktok, youtube | F28: 324450 | G28: 84 | H28: =IF(G28="","",RANK(G28,$G$5:$G$359)) -> 24 | I28: 56 | J28: =IF(I28="","",RANK(I28,$I$5:$I$359)) -> 151 | K28: 64.5 | L28: =IF(K28="","",RANK(K28,$K$5:$K$359)) -> 84 | M28: =IF(AND(N(G28)>=N(I28),N(G28)>=N(K28)),"The Pulse",IF(N(I28)>=N(K28),"The Lens","The Hub")) -> The Pulse | N28: Medium | O28: vendor_a, vendor_b
A29: Creator 627 | B29: CR00627 | C29: JP | D29: beauty | E29: instagram, tiktok, youtube | F29: 547829 | G29: 84 | H29: =IF(G29="","",RANK(G29,$G$5:$G$359)) -> 24 | I29: 14.1 | J29: =IF(I29="","",RANK(I29,$I$5:$I$359)) -> 333 | K29: 53.7 | L29: =IF(K29="","",RANK(K29,$K$5:$K$359)) -> 152 | M29: =IF(AND(N(G29)>=N(I29),N(G29)>=N(K29)),"The Pulse",IF(N(I29)>=N(K29),"The Lens","The Hub")) -> The Pulse | N29: Medium | O29: vendor_a, vendor_b
A30: Creator 1132 | B30: CR01132 | C30: DE | D30: education | E30: instagram, tiktok | F30: 114280 | G30: 83.2 | H30: =IF(G30="","",RANK(G30,$G$5:$G$359)) -> 26 | I30: 16.2 | J30: =IF(I30="","",RANK(I30,$I$5:$I$359)) -> 326 | K30: 43.8 | L30: =IF(K30="","",RANK(K30,$K$5:$K$359)) -> 208 | M30: =IF(AND(N(G30)>=N(I30),N(G30)>=N(K30)),"The Pulse",IF(N(I30)>=N(K30),"The Lens","The Hub")) -> The Pulse | N30: High | O30: vendor_b
A31: Creator 1325 | B31: CR01325 | C31: FR | D31: finance | E31: instagram, tiktok, youtube | F31: 188110 | G31: 83 | H31: =IF(G31="","",RANK(G31,$G$5:$G$359)) -> 27 | I31: 42.7 | J31: =IF(I31="","",RANK(I31,$I$5:$I$359)) -> 227 | K31: 64.9 | L31: =IF(K31="","",RANK(K31,$K$5:$K$359)) -> 83 | M31: =IF(AND(N(G31)>=N(I31),N(G31)>=N(K31)),"The Pulse",IF(N(I31)>=N(K31),"The Lens","The Hub")) -> The Pulse | N31: Medium | O31: vendor_a, vendor_b
A32: Creator 78 | B32: CR00078 | C32: GB | D32: comedy | E32: youtube | F32: 13930 | G32: 82.9 | H32: =IF(G32="","",RANK(G32,$G$5:$G$359)) -> 28 | I32: 36.7 | J32: =IF(I32="","",RANK(I32,$I$5:$I$359)) -> 257 | K32: 4.5 | L32: =IF(K32="","",RANK(K32,$K$5:$K$359)) -> 346 | M32: =IF(AND(N(G32)>=N(I32),N(G32)>=N(K32)),"The Pulse",IF(N(I32)>=N(K32),"The Lens","The Hub")) -> The Pulse | N32: Low | O32: vendor_b, vendor_c
... A113: Creator 570 | B113: CR00570 | C113: US | D113: finance | E113: instagram, tiktok, youtube | F113: 70481 | G113: 61.2 | H113: =IF(G113="","",RANK(G113,$G$5:$G$359)) -> 109 | I113: 70.9 | J113: =IF(I113="","",RANK(I113,$I$5:$I$359)) -> 68 | K113: 20.5 | L113: =IF(K113="","",RANK(K113,$K$5:$K$359)) -> 316 | M113: =IF(AND(N(G113)>=N(I113),N(G113)>=N(K113)),"The Pulse",IF(N(I113)>=N(K113),"The Lens","The Hub")) -> The Lens | N113: Medium | O113: vendor_a, vendor_b
A114: Creator 408 | B114: CR00408 | C114: MX | E114: instagram | F114: 120497 | G114: 61.1 | H114: =IF(G114="","",RANK(G114,$G$5:$G$359)) -> 110 | I114: 12.9 | J114: =IF(I114="","",RANK(I114,$I$5:$I$359)) -> 336 | K114: 85.8 | L114: =IF(K114="","",RANK(K114,$K$5:$K$359)) -> 17 | M114: =IF(AND(N(G114)>=N(I114),N(G114)>=N(K114)),"The Pulse",IF(N(I114)>=N(K114),"The Lens","The Hub")) -> The Hub | N114: Medium | O114: vendor_a
A115: Creator 180 | B115: CR00180 | C115: US | D115: music | E115: instagram, tiktok, youtube | F115: 88005 | G115: 60.9 | H115: =IF(G115="","",RANK(G115,$G$5:$G$359)) -> 111 | I115: 67.6 | J115: =IF(I115="","",RANK(I115,$I$5:$I$359)) -> 79 | K115: 56.4 | L115: =IF(K115="","",RANK(K115,$K$5:$K$359)) -> 135 | M115: =IF(AND(N(G115)>=N(I115),N(G115)>=N(K115)),"The Pulse",IF(N(I115)>=N(K115),"The Lens","The Hub")) -> The Lens | N115: Medium | O115: vendor_a, vendor_b
A116: Creator 1386 | B116: CR01386 | C116: BR | D116: food | E116: instagram | F116: 3737 | G116: 60.7 | H116: =IF(G116="","",RANK(G116,$G$5:$G$359)) -> 112 | I116: 81.7 | J116: =IF(I116="","",RANK(I116,$I$5:$I$359)) -> 31 | K116: 88.8 | L116: =IF(K116="","",RANK(K116,$K$5:$K$359)) -> 11 | M116: =IF(AND(N(G116)>=N(I116),N(G116)>=N(K116)),"The Pulse",IF(N(I116)>=N(K116),"The Lens","The Hub")) -> The Hub | N116: Medium | O116: vendor_a
A117: Creator 86 | B117: CR00086 | C117: US | D117: education | E117: instagram, tiktok, youtube | F117: 326218 | G117: 60.6 | H117: =IF(G117="","",RANK(G117,$G$5:$G$359)) -> 113 | I117: 33.6 | J117: =IF(I117="","",RANK(I117,$I$5:$I$359)) -> 270 | K117: 56.3 | L117: =IF(K117="","",RANK(K117,$K$5:$K$359)) -> 136 | M117: =IF(AND(N(G117)>=N(I117),N(G117)>=N(K117)),"The Pulse",IF(N(I117)>=N(K117),"The Lens","The Hub")) -> The Pulse | N117: Medium | O117: vendor_a, vendor_b
A118: Creator 709 | B118: CR00709 | C118: FR | D118: comedy | E118: instagram, tiktok, youtube | F118: 969434 | G118: 60.5 | H118: =IF(G118="","",RANK(G118,$G$5:$G$359)) -> 114 | I118: 33.3 | J118: =IF(I118="","",RANK(I118,$I$5:$I$359)) -> 273 | K118: 41.8 | L118: =IF(K118="","",RANK(K118,$K$5:$K$359)) -> 221 | M118: =IF(AND(N(G118)>=N(I118),N(G118)>=N(K118)),"The Pulse",IF(N(I118)>=N(K118),"The Lens","The Hub")) -> The Pulse | N118: Medium | O118: vendor_a, vendor_b
A119: Creator 552 | B119: CR00552 | C119: DE | D119: finance | E119: instagram, tiktok, youtube | F119: 295713 | G119: 60.4 | H119: =IF(G119="","",RANK(G119,$G$5:$G$359)) -> 115 | I119: 30.9 | J119: =IF(I119="","",RANK(I119,$I$5:$I$359)) -> 281 | K119: 36.2 | L119: =IF(K119="","",RANK(K119,$K$5:$K$359)) -> 263 | M119: =IF(AND(N(G119)>=N(I119),N(G119)>=N(K119)),"The Pulse",IF(N(I119)>=N(K119),"The Lens","The Hub")) -> The Pulse | N119: Medium | O119: vendor_a
A120: Creator 680 | B120: CR00680 | C120: IN | D120: beauty | E120: tiktok | F120: 76610 | G120: 60.3 | H120: =IF(G120="","",RANK(G120,$G$5:$G$359)) -> 116 | I120: 55.3 | J120: =IF(I120="","",RANK(I120,$I$5:$I$359)) -> 154 | K120: 30.5 | L120: =IF(K120="","",RANK(K120,$K$5:$K$359)) -> 292 | M120: =IF(AND(N(G120)>=N(I120),N(G120)>=N(K120)),"The Pulse",IF(N(I120)>=N(K120),"The Lens","The Hub")) -> The Pulse | N120: High | O120: vendor_b
A121: Creator 116 | B121: CR00116 | C121: US | D121: tech | E121: instagram | F121: 4540 | G121: 60.3 | H121: =IF(G121="","",RANK(G121,$G$5:$G$359)) -> 116 | I121: 57.7 | J121: =IF(I121="","",RANK(I121,$I$5:$I$359)) -> 138 | K121: 81.8 | L121: =IF(K121="","",RANK(K121,$K$5:$K$359)) -> 29 | M121: =IF(AND(N(G121)>=N(I121),N(G121)>=N(K121)),"The Pulse",IF(N(I121)>=N(K121),"The Lens","The Hub")) -> The Hub | N121: Medium | O121: vendor_a, vendor_b
...

Sheet Instagram
A1: Instagram leaderboard — one row per complete Instagram channel
A2: Ranks every requested channel on this platform that is filled, even if the creator's other channels aren't yet. Scores are 0–100 percentiles within the platform (The Lens also within size band).
A4: Creator | B4: Creator ID | C4: Handle | D4: Country | E4: Followers | F4: Size band | G4: 90d Reach Rate | H4: The Pulse score | I4: The Pulse rank | J4: 90d Growth Rate | K4: The Lens score | L4: The Lens rank | M4: 90d Meaningful Engagement Rate | N4: The Hub score | O4: The Hub rank | P4: Primary role | Q4: Confidence | R4: All requested channels filled | S4: Sources
A5: Creator 1343 | B5: CR01343 | C5: @creator1343_instagram | D5: DE | E5: 59960 | F5: micro | G5: 7.7815377 | H5: 100 | I5: =IF(H5="","",RANK(H5,$H$5:$H$430)) -> 1 | J5: 0.11491261 | K5: 60.8 | L5: =IF(K5="","",RANK(K5,$K$5:$K$430)) -> 166 | M5: 0.017974351 | N5: 4.9 | O5: =IF(N5="","",RANK(N5,$N$5:$N$430)) -> 369 | P5: =IF(AND(N(H5)>=N(K5),N(H5)>=N(N5)),"The Pulse",IF(N(K5)>=N(N5),"The Lens","The Hub")) -> The Pulse | Q5: High | R5: Yes | S5: vendor_b
A6: Creator 401 | B6: CR00401 | C6: @creator401_instagram | D6: GB | E6: 35380 | F6: micro | G6: 7.6251555 | H6: 99.8 | I6: =IF(H6="","",RANK(H6,$H$5:$H$430)) -> 2 | J6: 0.059916117 | K6: 32.3 | L6: =IF(K6="","",RANK(K6,$K$5:$K$430)) -> 282 | M6: 0.14179009 | N6: 53.8 | O6: =IF(N6="","",RANK(N6,$N$5:$N$430)) -> 174 | P6: =IF(AND(N(H6)>=N(K6),N(H6)>=N(N6)),"The Pulse",IF(N(K6)>=N(N6),"The Lens","The Hub")) -> The Pulse | Q6: High | R6: Yes | S6: vendor_b
A7: Creator 588 | B7: CR00588 | C7: @creator588_instagram | D7: FR | E7: 7490 | F7: nano | G7: 4.9392523 | H7: 99.6 | I7: =IF(H7="","",RANK(H7,$H$5:$H$430)) -> 3 | J7: 0.10147059 | K7: 53.5 | L7: =IF(K7="","",RANK(K7,$K$5:$K$430)) -> 197 | M7: 0.10925307 | N7: 39.9 | O7: =IF(N7="","",RANK(N7,$N$5:$N$430)) -> 232 | P7: =IF(AND(N(H7)>=N(K7),N(H7)>=N(N7)),"The Pulse",IF(N(K7)>=N(N7),"The Lens","The Hub")) -> The Pulse | Q7: High | R7: Yes | S7: vendor_b
A8: Creator 1492 | B8: CR01492 | C8: @creator1492_instagram | D8: MX | E8: 311650 | F8: mid | G8: 3.6281719 | H8: 99.4 | I8: =IF(H8="","",RANK(H8,$H$5:$H$430)) -> 4 | J8: 0.314757 | K8: 100 | L8: =IF(K8="","",RANK(K8,$K$5:$K$430)) -> 1 | M8: 0.28876507 | N8: 89.3 | O8: =IF(N8="","",RANK(N8,$N$5:$N$430)) -> 41 | P8: =IF(AND(N(H8)>=N(K8),N(H8)>=N(N8)),"The Pulse",IF(N(K8)>=N(N8),"The Lens","The Hub")) -> The Lens | Q8: Medium | R8: Yes | S8: vendor_a, vendor_b
A9: Creator 1133 | B9: CR01133 | C9: @creator1133_instagram | D9: CA | E9: 655880 | F9: mid | G9: 3.3905623 | H9: 99.2 | I9: =IF(H9="","",RANK(H9,$H$5:$H$430)) -> 5 | J9: -0.042329201 | K9: 5 | L9: =IF(K9="","",RANK(K9,$K$5:$K$430)) -> 406 | M9: 0.39870687 | N9: 97.7 | O9: =IF(N9="","",RANK(N9,$N$5:$N$430)) -> 10 | P9: =IF(AND(N(H9)>=N(K9),N(H9)>=N(N9)),"The Pulse",IF(N(K9)>=N(N9),"The Lens","The Hub")) -> The Pulse | Q9: High | R9: Yes | S9: vendor_b
A10: Creator 1290 | B10: CR01290 | C10: https://www.instagram.com/creator1290_instagram/ | D10: GB | E10: 37440 | F10: micro | G10: 2.850641 | H10: 99.1 | I10: =IF(H10="","",RANK(H10,$H$5:$H$430)) -> 6 | J10: 0.20930233 | K10: 92.8 | L10: =IF(K10="","",RANK(K10,$K$5:$K$430)) -> 33 | M10: 0.23446602 | N10: 80 | O10: =IF(N10="","",RANK(N10,$N$5:$N$430)) -> 80 | P10: =IF(AND(N(H10)>=N(K10),N(H10)>=N(N10)),"The Pulse",IF(N(K10)>=N(N10),"The Lens","The Hub")) -> The Pulse | Q10: High | R10: No | S10: vendor_b
A11: Creator 212 | B11: CR00212 | C11: @creator212_instagram | D11: JP | E11: 174450 | F11: mid | G11: 2.7063571 | H11: 98.9 | I11: =IF(H11="","",RANK(H11,$H$5:$H$430)) -> 7 | J11: 0.20986199 | K11: 95.7 | L11: =IF(K11="","",RANK(K11,$K$5:$K$430)) -> 20 | M11: 0.08980279 | N11: 31.9 | O11: =IF(N11="","",RANK(N11,$N$5:$N$430)) -> 264 | P11: =IF(AND(N(H11)>=N(K11),N(H11)>=N(N11)),"The Pulse",IF(N(K11)>=N(N11),"The Lens","The Hub")) -> The Pulse | Q11: High | R11: No | S11: vendor_b
A12: Creator 373 | B12: CR00373 | C12: https://www.instagram.com/creator373_instagram/ | D12: JP | E12: 20020 | F12: micro | G12: 2.6334665 | H12: 98.7 | I12: =IF(H12="","",RANK(H12,$H$5:$H$430)) -> 8 | J12: 0.12031337 | K12: 64.6 | L12: =IF(K12="","",RANK(K12,$K$5:$K$430)) -> 153 | M12: 0.1724 | N12: 65.7 | O12: =IF(N12="","",RANK(N12,$N$5:$N$430)) -> 132 | P12: =IF(AND(N(H12)>=N(K12),N(H12)>=N(N12)),"The Pulse",IF(N(K12)>=N(N12),"The Lens","The Hub")) -> The Pulse | Q12: Medium | R12: No | S12: vendor_a, vendor_b
A13: Creator 357 | B13: CR00357 | C13: @creator357_instagram | D13: MX | E13: 20574 | F13: micro | G13: 2.6261301 | H13: 98.5 | I13: =IF(H13="","",RANK(H13,$H$5:$H$430)) -> 9 | J13: 0.13174542 | K13: 70.1 | L13: =IF(K13="","",RANK(K13,$K$5:$K$430)) -> 129 | M13: 0.077169845 | N13: 24.9 | O13: =IF(N13="","",RANK(N13,$N$5:$N$430)) -> 292 | P13: =IF(AND(N(H13)>=N(K13),N(H13)>=N(N13)),"The Pulse",IF(N(K13)>=N(N13),"The Lens","The Hub")) -> The Pulse | Q13: Medium | R13: Yes | S13: vendor_a
A14: Creator 882 | B14: CR00882 | C14: @creator882_instagram | D14: IN | E14: 280270 | F14: mid | G14: 2.5718236 | H14: 98.3 | I14: =IF(H14="","",RANK(H14,$H$5:$H$430)) -> 10 | J14: -0.092553195 | K14: 1.4 | L14: =IF(K14="","",RANK(K14,$K$5:$K$430)) -> 421 | M14: 0.053863839 | N14: 17.2 | O14: =IF(N14="","",RANK(N14,$N$5:$N$430)) -> 320 | P14: =IF(AND(N(H14)>=N(K14),N(H14)>=N(N14)),"The Pulse",IF(N(K14)>=N(N14),"The Lens","The Hub")) -> The Pulse | Q14: Medium | R14: Yes | S14: vendor_a, vendor_b
A15: Creator 789 | B15: CR00789 | C15: https://www.instagram.com/creator789_instagram/ | D15: GB | E15: 3140 | F15: nano | G15: 2.5275101 | H15: 98.1 | I15: =IF(H15="","",RANK(H15,$H$5:$H$430)) -> 11 | J15: 0.12640056 | K15: 67.6 | L15: =IF(K15="","",RANK(K15,$K$5:$K$430)) -> 139 | M15: 0.27848101 | N15: 87.2 | O15: =IF(N15="","",RANK(N15,$N$5:$N$430)) -> 50 | P15: =IF(AND(N(H15)>=N(K15),N(H15)>=N(N15)),"The Pulse",IF(N(K15)>=N(N15),"The Lens","The Hub")) -> The Pulse | Q15: Low | R15: Yes | S15: vendor_b, vendor_c
A16: Creator 489 | B16: CR00489 | C16: @creator489_instagram | D16: CA | E16: 164740 | F16: mid | G16: 2.4872284 | H16: 97.7 | I16: =IF(H16="","",RANK(H16,$H$5:$H$430)) -> 12 | J16: 0.088542355 | K16: 55 | L16: =IF(K16="","",RANK(K16,$K$5:$K$430)) -> 189 | M16: 0.31161103 | N16: 91.8 | O16: =IF(N16="","",RANK(N16,$N$5:$N$430)) -> 32 | P16: =IF(AND(N(H16)>=N(K16),N(H16)>=N(N16)),"The Pulse",IF(N(K16)>=N(N16),"The Lens","The Hub")) -> The Pulse | Q16: High | R16: No | S16: vendor_b
... A23: Creator 189 | B23: CR00189 | C23: @creator189_instagram | D23: US | E23: 42010 | F23: micro | G23: 2.2732683 | H23: 96.4 | I23: =IF(H23="","",RANK(H23,$H$5:$H$430)) -> 19 | J23: 0.12086446 | K23: 65.3 | L23: =IF(K23="","",RANK(K23,$K$5:$K$430)) -> 148 | M23: 0.41080402 | N23: 98.8 | O23: =IF(N23="","",RANK(N23,$N$5:$N$430)) -> 6 | P23: =IF(AND(N(H23)>=N(K23),N(H23)>=N(N23)),"The Pulse",IF(N(K23)>=N(N23),"The Lens","The Hub")) -> The Hub | Q23: High | R23: Yes | S23: vendor_b
A24: Creator 1332 | B24: CR01332 | C24: @creator1332_instagram | D24: JP | E24: 2350 | F24: nano | G24: 2.1455319 | H24: 96.2 | I24: =IF(H24="","",RANK(H24,$H$5:$H$430)) -> 20 | J24: 0.059534467 | K24: 26.8 | L24: =IF(K24="","",RANK(K24,$K$5:$K$430)) -> 303 | M24: n/a – likes hidden | O24: =IF(N24="","",RANK(N24,$N$5:$N$430)) | P24: =IF(AND(N(H24)>=N(K24),N(H24)>=N(N24)),"The Pulse",IF(N(K24)>=N(N24),"The Lens","The Hub")) -> The Pulse | Q24: Medium | R24: Yes | S24: vendor_a, vendor_b
A25: Creator 368 | B25: CR00368 | C25: @creator368_instagram | D25: BR | E25: 18270 | F25: micro | G25: 2.1250137 | H25: 96 | I25: =IF(H25="","",RANK(H25,$H$5:$H$430)) -> 21 | J25: 0.20197368 | K25: 91.4 | L25: =IF(K25="","",RANK(K25,$K$5:$K$430)) -> 38 | M25: 0.14935065 | N25: 57.6 | O25: =IF(N25="","",RANK(N25,$N$5:$N$430)) -> 161 | P25: =IF(AND(N(H25)>=N(K25),N(H25)>=N(N25)),"The Pulse",IF(N(K25)>=N(N25),"The Lens","The Hub")) -> The Pulse | Q25: High | R25: No | S25: vendor_b
A26: Creator 1442 | B26: CR01442 | C26: @creator1442_instagram | D26: KR | E26: 19679 | F26: micro | G26: 2.1116927 | H26: 95.8 | I26: =IF(H26="","",RANK(H26,$H$5:$H$430)) -> 22 | J26: 0.0016797312 | K26: 9.6 | L26: =IF(K26="","",RANK(K26,$K$5:$K$430)) -> 383 | M26: 0.062545455 | N26: 21 | O26: =IF(N26="","",RANK(N26,$N$5:$N$430)) -> 306 | P26: =IF(AND(N(H26)>=N(K26),N(H26)>=N(N26)),"The Pulse",IF(N(K26)>=N(N26),"The Lens","The Hub")) -> The Pulse | Q26: Medium | R26: No | S26: vendor_a
A27: Creator 663 | B27: CR00663 | C27: @creator663_instagram | D27: GB | E27: 335870 | F27: mid | G27: 2.0898979 | H27: 95.7 | I27: =IF(H27="","",RANK(H27,$H$5:$H$430)) -> 23 | J27: 0.17396015 | K27: 87.1 | L27: =IF(K27="","",RANK(K27,$K$5:$K$430)) -> 57 | M27: 0.16346897 | N27: 63.9 | O27: =IF(N27="","",RANK(N27,$N$5:$N$430)) -> 138 | P27: =IF(AND(N(H27)>=N(K27),N(H27)>=N(N27)),"The Pulse",IF(N(K27)>=N(N27),"The Lens","The Hub")) -> The Pulse | Q27: High | R27: Yes | S27: vendor_b
A28: Creator 546 | B28: CR00546 | C28: @creator546_instagram | D28: US | E28: 85530 | F28: micro | G28: 2.0445458 | H28: 95.5 | I28: =IF(H28="","",RANK(H28,$H$5:$H$430)) -> 24 | J28: 0.090338134 | K28: 47.4 | L28: =IF(K28="","",RANK(K28,$K$5:$K$430)) -> 224 | M28: 0.079850903 | N28: 25.9 | O28: =IF(N28="","",RANK(N28,$N$5:$N$430)) -> 288 | P28: =IF(AND(N(H28)>=N(K28),N(H28)>=N(N28)),"The Pulse",IF(N(K28)>=N(N28),"The Lens","The Hub")) -> The Pulse | Q28: Medium | R28: Yes | S28: vendor_a, vendor_b
A29: Creator 84 | B29: CR00084 | C29: @creator84_instagram | D29: JP | E29: 180880 | F29: mid | G29: 2.0433271 | H29: 95.3 | I29: =IF(H29="","",RANK(H29,$H$5:$H$430)) -> 25 | J29: 0.13085339 | K29: 74.3 | L29: =IF(K29="","",RANK(K29,$K$5:$K$430)) -> 111 | M29: 0.011918697 | N29: 3 | O29: =IF(N29="","",RANK(N29,$N$5:$N$430)) -> 375 | P29: =IF(AND(N(H29)>=N(K29),N(H29)>=N(N29)),"The Pulse",IF(N(K29)>=N(N29),"The Lens","The Hub")) -> The Pulse | Q29: High | R29: No | S29: vendor_b
A30: Creator 620 | B30: CR00620 | C30: @creator620_instagram | D30: JP | E30: 852710 | F30: mid | G30: 2.0414946 | H30: 95.1 | I30: =IF(H30="","",RANK(H30,$H$5:$H$430)) -> 26 | J30: 0.069899624 | K30: 40.7 | L30: =IF(K30="","",RANK(K30,$K$5:$K$430)) -> 250 | M30: 0.19238726 | N30: 70.6 | O30: =IF(N30="","",RANK(N30,$N$5:$N$430)) -> 114 | P30: =IF(AND(N(H30)>=N(K30),N(H30)>=N(N30)),"The Pulse",IF(N(K30)>=N(N30),"The Lens","The Hub")) -> The Pulse | Q30: Medium | R30: Yes | S30: vendor_a, vendor_b
A31: Creator 246 | B31: CR00246 | C31: https://www.instagram.com/creator246_instagram/ | D31: US | E31: 132660 | F31: mid | G31: 2.0319539 | H31: 94.9 | I31: =IF(H31="","",RANK(H31,$H$5:$H$430)) -> 27 | J31: 0.061789659 | K31: 34.3 | L31: =IF(K31="","",RANK(K31,$K$5:$K$430)) -> 274 | M31: 0.13045868 | N31: 48.5 | O31: =IF(N31="","",RANK(N31,$N$5:$N$430)) -> 197 | P31: =IF(AND(N(H31)>=N(K31),N(H31)>=N(N31)),"The Pulse",IF(N(K31)>=N(N31),"The Lens","The Hub")) -> The Pulse | Q31: High | R31: Yes | S31: vendor_b
A32: Creator 374 | B32: CR00374 | C32: @creator374_instagram | D32: MX | E32: 7461 | F32: nano | G32: 1.9725238 | H32: 94.7 | I32: =IF(H32="","",RANK(H32,$H$5:$H$430)) -> 28 | J32: 0.051882137 | K32: 21.1 | L32: =IF(K32="","",RANK(K32,$K$5:$K$430)) -> 331 | M32: 0.13255814 | N32: 49.2 | O32: =IF(N32="","",RANK(N32,$N$5:$N$430)) -> 194 | P32: =IF(AND(N(H32)>=N(K32),N(H32)>=N(N32)),"The Pulse",IF(N(K32)>=N(N32),"The Lens","The Hub")) -> The Pulse | Q32: Medium | R32: No | S32: vendor_a
A33: Creator 694 | B33: CR00694 | C33: @creator694_instagram | D33: US | E33: 21860 | F33: micro | G33: 1.9100183 | H33: 94.5 | I33: =IF(H33="","",RANK(H33,$H$5:$H$430)) -> 29 | J33: 0.12045105 | K33: 64.9 | L33: =IF(K33="","",RANK(K33,$K$5:$K$430)) -> 150 | M33: 0.031919962 | N33: 9.8 | O33: =IF(N33="","",RANK(N33,$N$5:$N$430)) -> 348 | P33: =IF(AND(N(H33)>=N(K33),N(H33)>=N(N33)),"The Pulse",IF(N(K33)>=N(N33),"The Lens","The Hub")) -> The Pulse | Q33: High | R33: No | S33: vendor_b
A34: Creator 741 | B34: CR00741 | C34: @creator741_instagram | D34: MX | E34: 24050 | F34: micro | G34: 1.8939709 | H34: 94.3 | I34: =IF(H34="","",RANK(H34,$H$5:$H$430)) -> 30 | J34: 0.22641509 | K34: 95.5 | L34: =IF(K34="","",RANK(K34,$K$5:$K$430)) -> 21 | M34: 0.082191781 | N34: 27.3 | O34: =IF(N34="","",RANK(N34,$N$5:$N$430)) -> 282 | P34: =IF(AND(N(H34)>=N(K34),N(H34)>=N(N34)),"The Pulse",IF(N(K34)>=N(N34),"The Lens","The Hub")) -> The Lens | Q34: High | R34: Yes | S34: vendor_b
A35: Creator 1051 | B35: CR01051 | C35: @creator1051_instagram | D35: JP | E35: 39277 | F35: micro | G35: 1.8700512 | H35: 94.1 | I35: =IF(H35="","",RANK(H35,$H$5:$H$430)) -> 31 | J35: 0.10272896 | K35: 54.6 | L35: =IF(K35="","",RANK(K35,$K$5:$K$430)) -> 191 | M35: 0.25902579 | N35: 83.9 | O35: =IF(N35="","",RANK(N35,$N$5:$N$430)) -> 63 | P35: =IF(AND(N(H35)>=N(K35),N(H35)>=N(N35)),"The Pulse",IF(N(K35)>=N(N35),"The Lens","The Hub")) -> The Pulse | Q35: Medium | R35: No | S35: vendor_a
A36: Creator 366 | B36: CR00366 | C36: @creator366_instagram | D36: KR | E36: 136460 | F36: mid | G36: 1.8532171 | H36: 94 | I36: =IF(H36="","",RANK(H36,$H$5:$H$430)) -> 32 | J36: 0.014647929 | K36: 17.1 | L36: =IF(K36="","",RANK(K36,$K$5:$K$430)) -> 349 | M36: 0.11403703 | N36: 41.5 | O36: =IF(N36="","",RANK(N36,$N$5:$N$430)) -> 225 | P36: =IF(AND(N(H36)>=N(K36),N(H36)>=N(N36)),"The Pulse",IF(N(K36)>=N(N36),"The Lens","The Hub")) -> The Pulse | Q36: High | R36: No | S36: vendor_b
A37: Creator 230 | B37: CR00230 | C37: https://www.instagram.com/creator230_instagram/ | D37: BR | E37: 21650 | F37: micro | G37: 1.8462818 | H37: 93.8 | I37: =IF(H37="","",RANK(H37,$H$5:$H$430)) -> 33 | J37: 0.18112384 | K37: 87.3 | L37: =IF(K37="","",RANK(K37,$K$5:$K$430)) -> 55 | M37: 0.085635359 | N37: 29.4 | O37: =IF(N37="","",RANK(N37,$N$5:$N$430)) -> 274 | P37: =IF(AND(N(H37)>=N(K37),N(H37)>=N(N37)),"The Pulse",IF(N(K37)>=N(N37),"The Lens","The Hub")) -> The Pulse | Q37: High | R37: No | S37: vendor_b
A38: Creator 764 | B38: CR00764 | C38: @creator764_instagram | D38: IN | E38: 35610 | F38: micro | G38: 1.7772255 | H38: 93.6 | I38: =IF(H38="","",RANK(H38,$H$5:$H$430)) -> 34 | J38: 0.0063815656 | K38: 10.3 | L38: =IF(K38="","",RANK(K38,$K$5:$K$430)) -> 380 | M38: n/a – likes hidden | O38: =IF(N38="","",RANK(N38,$N$5:$N$430)) | P38: =IF(AND(N(H38)>=N(K38),N(H38)>=N(N38)),"The Pulse",IF(N(K38)>=N(N38),"The Lens","The Hub")) -> The Pulse | Q38: Medium | R38: No | S38: vendor_a, vendor_b
A39: Creator 41 | B39: CR00041 | C39: @creator41_instagram | D39: IN | E39: 20130 | F39: micro | G39: 1.7767511 | H39: 93.4 | I39: =IF(H39="","",RANK(H39,$H$5:$H$430)) -> 35 | J39: 0.097002725 | K39: 50.2 | L39: =IF(K39="","",RANK(K39,$K$5:$K$430)) -> 214 | M39: n/a – likes hidden | O39: =IF(N39="","",RANK(N39,$N$5:$N$430)) | P39: =IF(AND(N(H39)>=N(K39),N(H39)>=N(N39)),"The Pulse",IF(N(K39)>=N(N39),"The Lens","The Hub")) -> The Pulse | Q39: High | R39: Yes | S39: vendor_b
A40: Creator 86 | B40: CR00086 | C40: @creator86_instagram | D40: US | E40: 17620 | F40: micro | G40: 1.7559024 | H40: 93 | I40: =IF(H40="","",RANK(H40,$H$5:$H$430)) -> 36 | J40: 0.073735527 | K40: 40.2 | L40: =IF(K40="","",RANK(K40,$K$5:$K$430)) -> 252 | M40: 0.27635542 | N40: 86.7 | O40: =IF(N40="","",RANK(N40,$N$5:$N$430)) -> 52 | P40: =IF(AND(N(H40)>=N(K40),N(H40)>=N(N40)),"The Pulse",IF(N(K40)>=N(N40),"The Lens","The Hub")) -> The Pulse | Q40: High | R40: Yes | S40: vendor_b
A41: Creator 1106 | B41: CR01106 | C41: @creator1106_instagram | D41: GB | E41: 41140 | F41: micro | G41: 1.7097493 | H41: 92.2 | I41: =IF(H41="","",RANK(H41,$H$5:$H$430)) -> 37 | J41: -0.026272189 | K41: 4.5 | L41: =IF(K41="","",RANK(K41,$K$5:$K$430)) -> 408 | M41: 0.13428048 | N41: 50.3 | O41: =IF(N41="","",RANK(N41,$N$5:$N$430)) -> 189 | P41: =IF(AND(N(H41)>=N(K41),N(H41)>=N(N41)),"The Pulse",IF(N(K41)>=N(N41),"The Lens","The Hub")) -> The Pulse | Q41: Medium | R41: Yes | S41: vendor_a, vendor_b
A42: Creator 1268 | B42: CR01268 | C42: @creator1268_instagram | D42: CA | E42: 64560 | F42: micro | G42: 1.7063817 | H42: 92.1 | I42: =IF(H42="","",RANK(H42,$H$5:$H$430)) -> 38 | J42: -0.018397446 | K42: 6.5 | L42: =IF(K42="","",RANK(K42,$K$5:$K$430)) -> 398 | M42: 0.16371134 | N42: 64.1 | O42: =IF(N42="","",RANK(N42,$N$5:$N$430)) -> 137 | P42: =IF(AND(N(H42)>=N(K42),N(H42)>=N(N42)),"The Pulse",IF(N(K42)>=N(N42),"The Lens","The Hub")) -> The Pulse | Q42: High | R42: Yes | S42: vendor_b
A43: Creator 1168 | B43: CR01168 | C43: @creator1168_instagram | D43: BR | E43: 18230 | F43: micro | G43: 1.681514 | H43: 91.9 | I43: =IF(H43="","",RANK(H43,$H$5:$H$430)) -> 39 | J43: 0.16411239 | K43: 80.1 | L43: =IF(K43="","",RANK(K43,$K$5:$K$430)) -> 87 | M43: 0.36896878 | N43: 95.8 | O43: =IF(N43="","",RANK(N43,$N$5:$N$430)) -> 16 | P43: =IF(AND(N(H43)>=N(K43),N(H43)>=N(N43)),"The Pulse",IF(N(K43)>=N(N43),"The Lens","The Hub")) -> The Hub | Q43: High | R43: Yes | S43: vendor_b
A44: Creator 497 | B44: CR00497 | C44: https://www.instagram.com/creator497_instagram/ | D44: MX | E44: 19100 | F44: micro | G44: 1.6800524 | H44: 91.7 | I44: =IF(H44="","",RANK(H44,$H$5:$H$430)) -> 40 | J44: 0.10023041 | K44: 52.6 | L44: =IF(K44="","",RANK(K44,$K$5:$K$430)) -> 202 | M44: 0.094661283 | N44: 34 | O44: =IF(N44="","",RANK(N44,$N$5:$N$430)) -> 256 | P44: =IF(AND(N(H44)>=N(K44),N(H44)>=N(N44)),"The Pulse",IF(N(K44)>=N(N44),"The Lens","The Hub")) -> The Pulse | Q44: High | R44: Yes | S44: vendor_b
A45: Creator 1374 | B45: CR01374 | C45: @creator1374_instagram | D45: KR | E45: 8910 | F45: nano | G45: 1.6569024 | H45: 91.5 | I45: =IF(H45="","",RANK(H45,$H$5:$H$430)) -> 41 | J45: 0.25316456 | K45: 98.6 | L45: =IF(K45="","",RANK(K45,$K$5:$K$430)) -> 7 | M45: 0.10174881 | N45: 36.4 | O45: =IF(N45="","",RANK(N45,$N$5:$N$430)) -> 247 | P45: =IF(AND(N(H45)>=N(K45),N(H45)>=N(N45)),"The Pulse",IF(N(K45)>=N(N45),"The Lens","The Hub")) -> The Lens | Q45: High | R45: Yes | S45: vendor_b
A46: Creator 979 | B46: CR00979 | C46: https://www.instagram.com/creator979_instagram/ | D46: US | E46: 12720 | F46: micro | G46: 1.6352987 | H46: 91.3 | I46: =IF(H46="","",RANK(H46,$H$5:$H$430)) -> 42 | J46: 0.10872152 | K46: 57.4 | L46: =IF(K46="","",RANK(K46,$K$5:$K$430)) -> 183 | M46: 0.20472441 | N46: 74.8 | O46: =IF(N46="","",RANK(N46,$N$5:$N$430)) -> 97 | P46: =IF(AND(N(H46)>=N(K46),N(H46)>=N(N46)),"The Pulse",IF(N(K46)>=N(N46),"The Lens","The Hub")) -> The Pulse | Q46: Low | R46: Yes | S46: vendor_b, vendor_c
A47: Creator 591 | B47: CR00591 | C47: @creator591_instagram | D47: MX | E47: 76200 | F47: micro | G47: 1.6266667 | H47: 91.1 | I47: =IF(H47="","",RANK(H47,$H$5:$H$430)) -> 43 | J47: 0.0086035738 | K47: 11 | L47: =IF(K47="","",RANK(K47,$K$5:$K$430)) -> 377 | M47: 0.21472991 | N47: 75.8 | O47: =IF(N47="","",RANK(N47,$N$5:$N$430)) -> 94 | P47: =IF(AND(N(H47)>=N(K47),N(H47)>=N(N47)),"The Pulse",IF(N(K47)>=N(N47),"The Lens","The Hub")) -> The Pulse | Q47: High | R47: No | S47: vendor_b
...

Sheet TikTok
A1: TikTok leaderboard — one row per complete TikTok channel
A2: Ranks every requested channel on this platform that is filled, even if the creator's other channels aren't yet. Scores are 0–100 percentiles within the platform (The Lens also within size band).
A4: Creator | B4: Creator ID | C4: Handle | D4: Country | E4: Followers | F4: Size band | G4: 90d Reach Rate | H4: The Pulse score | I4: The Pulse rank | J4: 90d Growth Rate | K4: The Lens score | L4: The Lens rank | M4: 90d Meaningful Engagement Rate | N4: The Hub score | O4: The Hub rank | P4: Primary role | Q4: Confidence | R4: All requested channels filled | S4: Sources
A5: Creator 769 | B5: CR00769 | C5: @creator769_tiktok | D5: CA | E5: 5020 | F5: nano | G5: 25.621514 | H5: 100 | I5: =IF(H5="","",RANK(H5,$H$5:$H$389)) -> 1 | J5: 0.12304251 | K5: 56.6 | L5: =IF(K5="","",RANK(K5,$K$5:$K$389)) -> 169 | M5: 0.26677316 | N5: 83.9 | O5: =IF(N5="","",RANK(N5,$N$5:$N$389)) -> 62 | P5: =IF(AND(N(H5)>=N(K5),N(H5)>=N(N5)),"The Pulse",IF(N(K5)>=N(N5),"The Lens","The Hub")) -> The Pulse | Q5: Medium | R5: No | S5: vendor_a, vendor_b
A6: Creator 73 | B6: CR00073 | C6: @creator73_tiktok | D6: DE | E6: 410680 | F6: mid | G6: 19.609294 | H6: 99.8 | I6: =IF(H6="","",RANK(H6,$H$5:$H$389)) -> 2 | J6: 0.12923449 | K6: 75.2 | L6: =IF(K6="","",RANK(K6,$K$5:$K$389)) -> 93 | M6: 0.27406342 | N6: 85.2 | O6: =IF(N6="","",RANK(N6,$N$5:$N$389)) -> 56 | P6: =IF(AND(N(H6)>=N(K6),N(H6)>=N(N6)),"The Pulse",IF(N(K6)>=N(N6),"The Lens","The Hub")) -> The Pulse | Q6: High | R6: Yes | S6: vendor_b
A7: Creator 627 | B7: CR00627 | C7: @creator627_tiktok | D7: JP | E7: 201170 | F7: mid | G7: 18.173018 | H7: 99.6 | I7: =IF(H7="","",RANK(H7,$H$5:$H$389)) -> 3 | J7: -0.02107056 | K7: 7.6 | L7: =IF(K7="","",RANK(K7,$K$5:$K$389)) -> 359 | M7: 0.21154255 | N7: 71.5 | O7: =IF(N7="","",RANK(N7,$N$5:$N$389)) -> 111 | P7: =IF(AND(N(H7)>=N(K7),N(H7)>=N(N7)),"The Pulse",IF(N(K7)>=N(N7),"The Lens","The Hub")) -> The Pulse | Q7: High | R7: Yes | S7: vendor_b
A8: Creator 368 | B8: CR00368 | C8: @creator368_tiktok | D8: BR | E8: 37019 | F8: micro | G8: 17.850104 | H8: 99.4 | I8: =IF(H8="","",RANK(H8,$H$5:$H$389)) -> 4 | J8: 0.085442017 | K8: 51.6 | L8: =IF(K8="","",RANK(K8,$K$5:$K$389)) -> 189 | M8: 0.18388751 | N8: 65.3 | O8: =IF(N8="","",RANK(N8,$N$5:$N$389)) -> 138 | P8: =IF(AND(N(H8)>=N(K8),N(H8)>=N(N8)),"The Pulse",IF(N(K8)>=N(N8),"The Lens","The Hub")) -> The Pulse | Q8: Low | R8: No | S8: vendor_b, vendor_c
A9: Creator 125 | B9: CR00125 | C9: @creator125_tiktok | D9: CA | E9: 17460 | F9: micro | G9: 17.807732 | H9: 99.2 | I9: =IF(H9="","",RANK(H9,$H$5:$H$389)) -> 5 | J9: 0.16789298 | K9: 85.1 | L9: =IF(K9="","",RANK(K9,$K$5:$K$389)) -> 55 | M9: 0.030935943 | N9: 6.8 | O9: =IF(N9="","",RANK(N9,$N$5:$N$389)) -> 358 | P9: =IF(AND(N(H9)>=N(K9),N(H9)>=N(N9)),"The Pulse",IF(N(K9)>=N(N9),"The Lens","The Hub")) -> The Pulse | Q9: High | R9: No | S9: vendor_b
A10: Creator 1427 | B10: CR01427 | C10: @creator1427_tiktok | D10: BR | E10: 14650 | F10: micro | G10: 16.955085 | H10: 98.8 | I10: =IF(H10="","",RANK(H10,$H$5:$H$389)) -> 6 | J10: 0.14542611 | K10: 78.9 | L10: =IF(K10="","",RANK(K10,$K$5:$K$389)) -> 78 | M10: 0.32421499 | N10: 92.1 | O10: =IF(N10="","",RANK(N10,$N$5:$N$389)) -> 32 | P10: =IF(AND(N(H10)>=N(K10),N(H10)>=N(N10)),"The Pulse",IF(N(K10)>=N(N10),"The Lens","The Hub")) -> The Pulse | Q10: High | R10: Yes | S10: vendor_b
A11: Creator 522 | B11: CR00522 | C11: @creator522_tiktok | D11: IN | E11: 844210 | F11: mid | G11: 15.987804 | H11: 98.6 | I11: =IF(H11="","",RANK(H11,$H$5:$H$389)) -> 7 | J11: 0.0507443 | K11: 35.7 | L11: =IF(K11="","",RANK(K11,$K$5:$K$389)) -> 253 | M11: 0.056393171 | N11: 13.7 | O11: =IF(N11="","",RANK(N11,$N$5:$N$389)) -> 331 | P11: =IF(AND(N(H11)>=N(K11),N(H11)>=N(N11)),"The Pulse",IF(N(K11)>=N(N11),"The Lens","The Hub")) -> The Pulse | Q11: High | R11: Yes | S11: vendor_b
A12: Creator 889 | B12: CR00889 | C12: @creator889_tiktok | D12: IN | E12: 64513 | F12: micro | G12: 15.765799 | H12: 98.4 | I12: =IF(H12="","",RANK(H12,$H$5:$H$389)) -> 8 | J12: -0.030885247 | K12: 6.9 | L12: =IF(K12="","",RANK(K12,$K$5:$K$389)) -> 361 | M12: 0.44009116 | N12: 98.5 | O12: =IF(N12="","",RANK(N12,$N$5:$N$389)) -> 7 | P12: =IF(AND(N(H12)>=N(K12),N(H12)>=N(N12)),"The Pulse",IF(N(K12)>=N(N12),"The Lens","The Hub")) -> The Hub | Q12: Medium | R12: No | S12: vendor_a
A13: Creator 1204 | B13: CR01204 | C13: @creator1204_tiktok | D13: CA | E13: 57158 | F13: micro | G13: 15.713618 | H13: 98.2 | I13: =IF(H13="","",RANK(H13,$H$5:$H$389)) -> 9 | J13: 0.17623575 | K13: 87.3 | L13: =IF(K13="","",RANK(K13,$K$5:$K$389)) -> 47 | M13: 0.26622174 | N13: 83.7 | O13: =IF(N13="","",RANK(N13,$N$5:$N$389)) -> 63 | P13: =IF(AND(N(H13)>=N(K13),N(H13)>=N(N13)),"The Pulse",IF(N(K13)>=N(N13),"The Lens","The Hub")) -> The Pulse | Q13: Medium | R13: Yes | S13: vendor_a
A14: Creator 860 | B14: CR00860 | C14: @creator860_tiktok | D14: MX | E14: 54360 | F14: micro | G14: 15.626306 | H14: 98 | I14: =IF(H14="","",RANK(H14,$H$5:$H$389)) -> 10 | J14: 0.17129929 | K14: 85.8 | L14: =IF(K14="","",RANK(K14,$K$5:$K$389)) -> 52 | M14: 0.077877575 | N14: 24.5 | O14: =IF(N14="","",RANK(N14,$N$5:$N$389)) -> 292 | P14: =IF(AND(N(H14)>=N(K14),N(H14)>=N(N14)),"The Pulse",IF(N(K14)>=N(N14),"The Lens","The Hub")) -> The Pulse | Q14: High | R14: Yes | S14: vendor_b
A15: Creator 182 | B15: CR00182 | C15: @creator182_tiktok | D15: US | E15: 123830 | F15: mid | G15: 15.601793 | H15: 97.8 | I15: =IF(H15="","",RANK(H15,$H$5:$H$389)) -> 11 | J15: 0.077157272 | K15: 51 | L15: =IF(K15="","",RANK(K15,$K$5:$K$389)) -> 192 | M15: 0.13326301 | N15: 50.6 | O15: =IF(N15="","",RANK(N15,$N$5:$N$389)) -> 190 | P15: =IF(AND(N(H15)>=N(K15),N(H15)>=N(N15)),"The Pulse",IF(N(K15)>=N(N15),"The Lens","The Hub")) -> The Pulse | Q15: High | R15: Yes | S15: vendor_b
A16: Creator 401 | B16: CR00401 | C16: @creator401_tiktok | D16: GB | E16: 119732 | F16: mid | G16: 15.011559 | H16: 97.6 | I16: =IF(H16="","",RANK(H16,$H$5:$H$389)) -> 12 | J16: 0.052154275 | K16: 36.9 | L16: =IF(K16="","",RANK(K16,$K$5:$K$389)) -> 249 | M16: 0.36907804 | N16: 95.6 | O16: =IF(N16="","",RANK(N16,$N$5:$N$389)) -> 19 | P16: =IF(AND(N(H16)>=N(K16),N(H16)>=N(N16)),"The Pulse",IF(N(K16)>=N(N16),"The Lens","The Hub")) -> The Pulse | Q16: Low | R16: Yes | S16: vendor_b, vendor_c
... A213: Creator 303 | B213: CR00303 | C213: https://www.tiktok.com/@creator303_tiktok | D213: CA | E213: 146730 | F213: mid | G213: 2.8383971 | H213: 44.2 | I213: =IF(H213="","",RANK(H213,$H$5:$H$389)) -> 209 | J213: 0.13322521 | K213: 77.1 | L213: =IF(K213="","",RANK(K213,$K$5:$K$389)) -> 85 | M213: 0.13288312 | N213: 50.3 | O213: =IF(N213="","",RANK(N213,$N$5:$N$389)) -> 191 | P213: =IF(AND(N(H213)>=N(K213),N(H213)>=N(N213)),"The Pulse",IF(N(K213)>=N(N213),"The Lens","The Hub")) -> The Lens | Q213: High | R213: No | S213: vendor_b
A214: Creator 1257 | B214: CR01257 | C214: @creator1257_tiktok | E214: 172540 | F214: mid | G214: 2.8321143 | H214: 44 | I214: =IF(H214="","",RANK(H214,$H$5:$H$389)) -> 210 | J214: 0.026473913 | K214: 23.6 | L214: =IF(K214="","",RANK(K214,$K$5:$K$389)) -> 298 | M214: 0.37419313 | N214: 95.8 | O214: =IF(N214="","",RANK(N214,$N$5:$N$389)) -> 18 | P214: =IF(AND(N(H214)>=N(K214),N(H214)>=N(N214)),"The Pulse",IF(N(K214)>=N(N214),"The Lens","The Hub")) -> The Hub | Q214: High | R214: No | S214: vendor_b
A215: Creator 501 | B215: CR00501 | C215: @creator501_tiktok | D215: JP | E215: 124880 | F215: mid | G215: 2.815639 | H215: 43.8 | I215: =IF(H215="","",RANK(H215,$H$5:$H$389)) -> 211 | J215: 0.067898067 | K215: 43.9 | L215: =IF(K215="","",RANK(K215,$K$5:$K$389)) -> 220 | M215: 0.12753711 | N215: 48.3 | O215: =IF(N215="","",RANK(N215,$N$5:$N$389)) -> 199 | P215: =IF(AND(N(H215)>=N(K215),N(H215)>=N(N215)),"The Pulse",IF(N(K215)>=N(N215),"The Lens","The Hub")) -> The Hub | Q215: High | R215: No | S215: vendor_b
A216: Creator 1002 | B216: CR01002 | C216: @creator1002_tiktok | D216: IN | E216: 155440 | F216: mid | G216: 2.8068387 | H216: 43.6 | I216: =IF(H216="","",RANK(H216,$H$5:$H$389)) -> 212 | J216: 0.043501611 | K216: 30.6 | L216: =IF(K216="","",RANK(K216,$K$5:$K$389)) -> 274 | M216: 0.085701514 | N216: 29.6 | O216: =IF(N216="","",RANK(N216,$N$5:$N$389)) -> 275 | P216: =IF(AND(N(H216)>=N(K216),N(H216)>=N(N216)),"The Pulse",IF(N(K216)>=N(N216),"The Lens","The Hub")) -> The Pulse | Q216: High | R216: Yes | S216: vendor_b
A217: Creator 882 | B217: CR00882 | C217: @creator882_tiktok | D217: IN | E217: 109220 | F217: mid | G217: 2.7884179 | H217: 43.4 | I217: =IF(H217="","",RANK(H217,$H$5:$H$389)) -> 213 | J217: 0.11255985 | K217: 68.8 | L217: =IF(K217="","",RANK(K217,$K$5:$K$389)) -> 113 | M217: 0.071321581 | N217: 21.2 | O217: =IF(N217="","",RANK(N217,$N$5:$N$389)) -> 303 | P217: =IF(AND(N(H217)>=N(K217),N(H217)>=N(N217)),"The Pulse",IF(N(K217)>=N(N217),"The Lens","The Hub")) -> The Lens | Q217: High | R217: Yes | S217: vendor_b
A218: Creator 505 | B218: CR00505 | C218: https://www.tiktok.com/@creator505_tiktok | D218: FR | E218: 5810 | F218: nano | G218: 2.7741824 | H218: 43.2 | I218: =IF(H218="","",RANK(H218,$H$5:$H$389)) -> 214 | J218: 0.09742229 | K218: 37.7 | L218: =IF(K218="","",RANK(K218,$K$5:$K$389)) -> 245 | M218: 0.016246954 | N218: 2.2 | O218: =IF(N218="","",RANK(N218,$N$5:$N$389)) -> 376 | P218: =IF(AND(N(H218)>=N(K218),N(H218)>=N(N218)),"The Pulse",IF(N(K218)>=N(N218),"The Lens","The Hub")) -> The Pulse | Q218: Low | R218: No | S218: vendor_b, vendor_c
A219: Creator 358 | B219: CR00358 | C219: @creator358_tiktok | D219: JP | E219: 173470 | F219: mid | G219: 2.7494149 | H219: 42.8 | I219: =IF(H219="","",RANK(H219,$H$5:$H$389)) -> 215 | J219: 0.10624322 | K219: 65 | L219: =IF(K219="","",RANK(K219,$K$5:$K$389)) -> 132 | M219: 0.016442652 | N219: 2.6 | O219: =IF(N219="","",RANK(N219,$N$5:$N$389)) -> 374 | P219: =IF(AND(N(H219)>=N(K219),N(H219)>=N(N219)),"The Pulse",IF(N(K219)>=N(N219),"The Lens","The Hub")) -> The Lens | Q219: High | R219: Yes | S219: vendor_b
A220: Creator 1187 | B220: CR01187 | C220: @creator1187_tiktok | D220: KR | E220: 28430 | F220: micro | G220: 2.7087584 | H220: 42.2 | I220: =IF(H220="","",RANK(H220,$H$5:$H$389)) -> 216 | J220: 0.041773543 | K220: 26.9 | L220: =IF(K220="","",RANK(K220,$K$5:$K$389)) -> 287 | M220: 0.041204888 | N220: 8.8 | O220: =IF(N220="","",RANK(N220,$N$5:$N$389)) -> 352 | P220: =IF(AND(N(H220)>=N(K220),N(H220)>=N(N220)),"The Pulse",IF(N(K220)>=N(N220),"The Lens","The Hub")) -> The Pulse | Q220: High | R220: No | S220: vendor_b
A221: Creator 321 | B221: CR00321 | C221: @creator321_tiktok | D221: JP | E221: 3860 | F221: nano | G221: 2.7059585 | H221: 42 | I221: =IF(H221="","",RANK(H221,$H$5:$H$389)) -> 217 | J221: 0.096253602 | K221: 34 | L221: =IF(K221="","",RANK(K221,$K$5:$K$389)) -> 260 | M221: 0.15608466 | N221: 57.6 | O221: =IF(N221="","",RANK(N221,$N$5:$N$389)) -> 166 | P221: =IF(AND(N(H221)>=N(K221),N(H221)>=N(N221)),"The Pulse",IF(N(K221)>=N(N221),"The Lens","The Hub")) -> The Hub | Q221: Medium | R221: Yes | S221: vendor_a, vendor_b
A222: Creator 158 | B222: CR00158 | C222: https://www.tiktok.com/@creator158_tiktok | D222: CA | E222: 211630 | F222: mid | G222: 2.6824458 | H222: 41.7 | I222: =IF(H222="","",RANK(H222,$H$5:$H$389)) -> 218 | J222: 0.076833053 | K222: 50.3 | L222: =IF(K222="","",RANK(K222,$K$5:$K$389)) -> 194 | M222: 0.22936686 | N222: 76.6 | O222: =IF(N222="","",RANK(N222,$N$5:$N$389)) -> 90 | P222: =IF(AND(N(H222)>=N(K222),N(H222)>=N(N222)),"The Pulse",IF(N(K222)>=N(N222),"The Lens","The Hub")) -> The Hub | Q222: High | R222: No | S222: vendor_b
A223: Creator 351 | B223: CR00351 | C223: @creator351_tiktok | D223: US | E223: 64610 | F223: micro | G223: 2.6771088 | H223: 41.5 | I223: =IF(H223="","",RANK(H223,$H$5:$H$389)) -> 219 | J223: 0.10425568 | K223: 60 | L223: =IF(K223="","",RANK(K223,$K$5:$K$389)) -> 152 | M223: 0.1780706 | N223: 63.8 | O223: =IF(N223="","",RANK(N223,$N$5:$N$389)) -> 144 | P223: =IF(AND(N(H223)>=N(K223),N(H223)>=N(N223)),"The Pulse",IF(N(K223)>=N(N223),"The Lens","The Hub")) -> The Hub | Q223: High | R223: No | S223: vendor_b
A224: Creator 431 | B224: CR00431 | C224: @creator431_tiktok | D224: BR | E224: 36080 | F224: micro | G224: 2.6764967 | H224: 41.3 | I224: =IF(H224="","",RANK(H224,$H$5:$H$389)) -> 220 | J224: 0.13352183 | K224: 74.2 | L224: =IF(K224="","",RANK(K224,$K$5:$K$389)) -> 96 | M224: 0.11547344 | N224: 43 | O224: =IF(N224="","",RANK(N224,$N$5:$N$389)) -> 219 | P224: =IF(AND(N(H224)>=N(K224),N(H224)>=N(N224)),"The Pulse",IF(N(K224)>=N(N224),"The Lens","The Hub")) -> The Lens | Q224: High | R224: Yes | S224: vendor_b
A225: Creator 809 | B225: CR00809 | C225: https://www.tiktok.com/@creator809_tiktok | D225: DE | E225: 20010 | F225: micro | G225: 2.6736632 | H225: 41.1 | I225: =IF(H225="","",RANK(H225,$H$5:$H$389)) -> 221 | J225: 0.068910256 | K225: 40.4 | L225: =IF(K225="","",RANK(K225,$K$5:$K$389)) -> 234 | M225: 0.10707457 | N225: 40.4 | O225: =IF(N225="","",RANK(N225,$N$5:$N$389)) -> 230 | P225: =IF(AND(N(H225)>=N(K225),N(H225)>=N(N225)),"The Pulse",IF(N(K225)>=N(N225),"The Lens","The Hub")) -> The Pulse | Q225: High | R225: Yes | S225: vendor_b
A226: Creator 313 | B226: CR00313 | C226: @creator313_tiktok | D226: KR | E226: 171990 | F226: mid | G226: 2.6191639 | H226: 40.9 | I226: =IF(H226="","",RANK(H226,$H$5:$H$389)) -> 222 | J226: 0.14006364 | K226: 81.5 | L226: =IF(K226="","",RANK(K226,$K$5:$K$389)) -> 68 | M226: 0.27263452 | N226: 85 | O226: =IF(N226="","",RANK(N226,$N$5:$N$389)) -> 57 | P226: =IF(AND(N(H226)>=N(K226),N(H226)>=N(N226)),"The Pulse",IF(N(K226)>=N(N226),"The Lens","The Hub")) -> The Hub | Q226: High | R226: Yes | S226: vendor_b
... A379: Creator 70 | B379: CR00070 | C379: @creator70_tiktok | D379: IN | E379: 11820 | F379: micro | G379: 0.66497462 | H379: 2.8 | I379: =IF(H379="","",RANK(H379,$H$5:$H$389)) -> 375 | J379: 0.10261194 | K379: 59.6 | L379: =IF(K379="","",RANK(K379,$K$5:$K$389)) -> 154 | M379: 0.29511278 | N379: 87.9 | O379: =IF(N379="","",RANK(N379,$N$5:$N$389)) -> 47 | P379: =IF(AND(N(H379)>=N(K379),N(H379)>=N(N379)),"The Pulse",IF(N(K379)>=N(N379),"The Lens","The Hub")) -> The Hub | Q379: High | R379: Yes | S379: vendor_b
A380: Creator 871 | B380: CR00871 | C380: @creator871_tiktok | E380: 178857 | F380: mid | G380: 0.61840465 | H380: 2.4 | I380: =IF(H380="","",RANK(H380,$H$5:$H$389)) -> 376 | J380: 0.1313261 | K380: 75.8 | L380: =IF(K380="","",RANK(K380,$K$5:$K$389)) -> 90 | M380: 0.18307742 | N380: 64.7 | O380: =IF(N380="","",RANK(N380,$N$5:$N$389)) -> 140 | P380: =IF(AND(N(H380)>=N(K380),N(H380)>=N(N380)),"The Pulse",IF(N(K380)>=N(N380),"The Lens","The Hub")) -> The Lens | Q380: Medium | R380: No | S380: vendor_a
A381: Creator 573 | B381: CR00573 | C381: https://www.tiktok.com/@creator573_tiktok | D381: BR | E381: 95130 | F381: micro | G381: 0.58871019 | H381: 2.2 | I381: =IF(H381="","",RANK(H381,$H$5:$H$389)) -> 377 | J381: 0.0080534068 | K381: 15.3 | L381: =IF(K381="","",RANK(K381,$K$5:$K$389)) -> 327 | M381: 0.22268557 | N381: 74.6 | O381: =IF(N381="","",RANK(N381,$N$5:$N$389)) -> 98 | P381: =IF(AND(N(H381)>=N(K381),N(H381)>=N(N381)),"The Pulse",IF(N(K381)>=N(N381),"The Lens","The Hub")) -> The Hub | Q381: High | R381: Yes | S381: vendor_b
A382: Creator 1270 | B382: CR01270 | C382: https://www.tiktok.com/@creator1270_tiktok | D382: FR | E382: 366330 | F382: mid | G382: 0.55879944 | H382: 2 | I382: =IF(H382="","",RANK(H382,$H$5:$H$389)) -> 378 | J382: 0.053126348 | K382: 37.6 | L382: =IF(K382="","",RANK(K382,$K$5:$K$389)) -> 246 | M382: 0.047170935 | N382: 11.3 | O382: =IF(N382="","",RANK(N382,$N$5:$N$389)) -> 342 | P382: =IF(AND(N(H382)>=N(K382),N(H382)>=N(N382)),"The Pulse",IF(N(K382)>=N(N382),"The Lens","The Hub")) -> The Lens | Q382: High | R382: No | S382: vendor_b
A383: Creator 1321 | B383: CR01321 | C383: https://www.tiktok.com/@creator1321_tiktok | D383: FR | E383: 264420 | F383: mid | G383: 0.5144694 | H383: 1.8 | I383: =IF(H383="","",RANK(H383,$H$5:$H$389)) -> 379 | J383: 0.033819447 | K383: 26.1 | L383: =IF(K383="","",RANK(K383,$K$5:$K$389)) -> 288 | M383: 0.12054264 | N383: 45.3 | O383: =IF(N383="","",RANK(N383,$N$5:$N$389)) -> 212 | P383: =IF(AND(N(H383)>=N(K383),N(H383)>=N(N383)),"The Pulse",IF(N(K383)>=N(N383),"The Lens","The Hub")) -> The Hub | Q383: High | R383: Yes | S383: vendor_b
A384: Creator 895 | B384: CR00895 | C384: https://www.tiktok.com/@creator895_tiktok | D384: US | E384: 53350 | F384: micro | G384: 0.51147149 | H384: 1.6 | I384: =IF(H384="","",RANK(H384,$H$5:$H$389)) -> 380 | J384: 0.10684647 | K384: 62.9 | L384: =IF(K384="","",RANK(K384,$K$5:$K$389)) -> 141 | M384: 0.13950276 | N384: 52.3 | O384: =IF(N384="","",RANK(N384,$N$5:$N$389)) -> 184 | P384: =IF(AND(N(H384)>=N(K384),N(H384)>=N(N384)),"The Pulse",IF(N(K384)>=N(N384),"The Lens","The Hub")) -> The Lens | Q384: Medium | R384: No | S384: vendor_a, vendor_b
A385: Creator 317 | B385: CR00317 | C385: @creator317_tiktok | D385: FR | E385: 29170 | F385: micro | G385: 0.47994515 | H385: 1.4 | I385: =IF(H385="","",RANK(H385,$H$5:$H$389)) -> 381 | J385: 0.11762452 | K385: 67.3 | L385: =IF(K385="","",RANK(K385,$K$5:$K$389)) -> 121 | M385: 0.14829659 | N385: 54.5 | O385: =IF(N385="","",RANK(N385,$N$5:$N$389)) -> 179 | P385: =IF(AND(N(H385)>=N(K385),N(H385)>=N(N385)),"The Pulse",IF(N(K385)>=N(N385),"The Lens","The Hub")) -> The Lens | Q385: High | R385: No | S385: vendor_b
A386: Creator 1374 | B386: CR01374 | C386: https://www.tiktok.com/@creator1374_tiktok | D386: KR | E386: 137380 | F386: mid | G386: 0.43148202 | H386: 0.8 | I386: =IF(H386="","",RANK(H386,$H$5:$H$389)) -> 382 | J386: 0.12717427 | K386: 73.9 | L386: =IF(K386="","",RANK(K386,$K$5:$K$389)) -> 97 | M386: 0.13048882 | N386: 49.4 | O386: =IF(N386="","",RANK(N386,$N$5:$N$389)) -> 194 | P386: =IF(AND(N(H386)>=N(K386),N(H386)>=N(N386)),"The Pulse",IF(N(K386)>=N(N386),"The Lens","The Hub")) -> The Lens | Q386: High | R386: Yes | S386: vendor_b
A387: Creator 1436 | B387: CR01436 | C387: @creator1436_tiktok | D387: FR | E387: 99650 | F387: micro | G387: 0.40830908 | H387: 0.6 | I387: =IF(H387="","",RANK(H387,$H$5:$H$389)) -> 383 | J387: 0.1418586 | K387: 77.1 | L387: =IF(K387="","",RANK(K387,$K$5:$K$389)) -> 85 | M387: 0.32296432 | N387: 91.8 | O387: =IF(N387="","",RANK(N387,$N$5:$N$389)) -> 33 | P387: =IF(AND(N(H387)>=N(K387),N(H387)>=N(N387)),"The Pulse",IF(N(K387)>=N(N387),"The Lens","The Hub")) -> The Hub | Q387: High | R387: Yes | S387: vendor_b
A388: Creator 663 | B388: CR00663 | C388: @creator663_tiktok | D388: GB | E388: 20780 | F388: micro | G388: 0.34523346 | H388: 0.4 | I388: =IF(H388="","",RANK(H388,$H$5:$H$389)) -> 384 | J388: 0.09483667 | K388: 54.9 | L388: =IF(K388="","",RANK(K388,$K$5:$K$389)) -> 175 | M388: 0.17132867 | N388: 62 | O388: =IF(N388="","",RANK(N388,$N$5:$N$389)) -> 150 | P388: =IF(AND(N(H388)>=N(K388),N(H388)>=N(N388)),"The Pulse",IF(N(K388)>=N(N388),"The Lens","The Hub")) -> The Hub | Q388: Medium | R388: Yes | S388: vendor_a, vendor_b
A389: Creator 360 | B389: CR00360 | C389: @creator360_tiktok | D389: US | E389: 217990 | F389: mid | G389: 0.27500803 | H389: 0.2 | I389: =IF(H389="","",RANK(H389,$H$5:$H$389)) -> 385 | J389: 0.045515588 | K389: 31.2 | L389: =IF(K389="","",RANK(K389,$K$5:$K$389)) -> 272 | M389: 0.23544034 | N389: 77.7 | O389: =IF(N389="","",RANK(N389,$N$5:$N$389)) -> 87 | P389: =IF(AND(N(H389)>=N(K389),N(H389)>=N(N389)),"The Pulse",IF(N(K389)>=N(N389),"The Lens","The Hub")) -> The Hub | Q389: High | R389: No | S389: vendor_b

Sheet YouTube
A1: YouTube leaderboard — one row per complete YouTube channel
A2: Ranks every requested channel on this platform that is filled, even if the creator's other channels aren't yet. Scores are 0–100 percentiles within the platform (The Lens also within size band).
A4: Creator | B4: Creator ID | C4: Handle | D4: Country | E4: Followers | F4: Size band | G4: 90d Reach Rate | H4: The Pulse score | I4: The Pulse rank | J4: 90d Growth Rate | K4: The Lens score | L4: The Lens rank | M4: 90d Meaningful Engagement Rate | N4: The Hub score | O4: The Hub rank | P4: Primary role | Q4: Confidence | R4: All requested channels filled | S4: Sources
A5: Creator 390 | B5: CR00390 | C5: @creator390_youtube | D5: GB | E5: 48271 | F5: micro | G5: 10.081353 | H5: 100 | I5: =IF(H5="","",RANK(H5,$H$5:$H$525)) -> 1 | J5: 0.11290174 | K5: 59.1 | L5: =IF(K5="","",RANK(K5,$K$5:$K$525)) -> 213 | M5: 0.061196514 | N5: 39.1 | O5: =IF(N5="","",RANK(N5,$N$5:$N$525)) -> 318 | P5: =IF(AND(N(H5)>=N(K5),N(H5)>=N(N5)),"The Pulse",IF(N(K5)>=N(N5),"The Lens","The Hub")) -> The Pulse | Q5: Medium | R5: Yes | S5: vendor_a
A6: Creator 1191 | B6: CR01191 | C6: @creator1191_youtube | D6: CA | E6: 22258 | F6: micro | G6: 9.1193728 | H6: 99.8 | I6: =IF(H6="","",RANK(H6,$H$5:$H$525)) -> 2 | J6: 0.083325221 | K6: 41.9 | L6: =IF(K6="","",RANK(K6,$K$5:$K$525)) -> 304 | M6: 0.24812883 | N6: 92.3 | O6: =IF(N6="","",RANK(N6,$N$5:$N$525)) -> 41 | P6: =IF(AND(N(H6)>=N(K6),N(H6)>=N(N6)),"The Pulse",IF(N(K6)>=N(N6),"The Lens","The Hub")) -> The Pulse | Q6: Medium | R6: No | S6: vendor_a
A7: Creator 361 | B7: CR00361 | C7: @creator361_youtube | D7: GB | E7: 9430 | F7: nano | G7: 7.7407211 | H7: 99.6 | I7: =IF(H7="","",RANK(H7,$H$5:$H$525)) -> 3 | J7: 0.061936937 | K7: 30 | L7: =IF(K7="","",RANK(K7,$K$5:$K$525)) -> 365 | M7: 0.21223529 | N7: 87.5 | O7: =IF(N7="","",RANK(N7,$N$5:$N$525)) -> 67 | P7: =IF(AND(N(H7)>=N(K7),N(H7)>=N(N7)),"The Pulse",IF(N(K7)>=N(N7),"The Lens","The Hub")) -> The Pulse | Q7: High | R7: Yes | S7: vendor_b
A8: Creator 381 | B8: CR00381 | C8: @creator381_youtube | D8: CA | E8: 35228 | F8: micro | G8: 7.3576984 | H8: 99.5 | I8: =IF(H8="","",RANK(H8,$H$5:$H$525)) -> 4 | J8: 0.10101263 | K8: 53.2 | L8: =IF(K8="","",RANK(K8,$K$5:$K$525)) -> 244 | M8: 0.15530203 | N8: 74.9 | O8: =IF(N8="","",RANK(N8,$N$5:$N$525)) -> 130 | P8: =IF(AND(N(H8)>=N(K8),N(H8)>=N(N8)),"The Pulse",IF(N(K8)>=N(N8),"The Lens","The Hub")) -> The Pulse | Q8: Medium | R8: No | S8: vendor_a
A9: Creator 581 | B9: CR00581 | C9: @creator581_youtube | D9: JP | E9: 89220 | F9: micro | G9: 6.8933983 | H9: 99.3 | I9: =IF(H9="","",RANK(H9,$H$5:$H$525)) -> 5 | J9: 0.046078087 | K9: 26.3 | L9: =IF(K9="","",RANK(K9,$K$5:$K$525)) -> 385 | M9: 0.12727475 | N9: 67.4 | O9: =IF(N9="","",RANK(N9,$N$5:$N$525)) -> 168 | P9: =IF(AND(N(H9)>=N(K9),N(H9)>=N(N9)),"The Pulse",IF(N(K9)>=N(N9),"The Lens","The Hub")) -> The Pulse | Q9: High | R9: Yes | S9: vendor_b
